[2019-06-12 22:45:22 +0800] [26150] [INFO] Starting gunicorn 19.9.0
[2019-06-12 22:45:22 +0800] [26150] [INFO] Listening at: http://0.0.0.0:8000 (26150)
[2019-06-12 22:45:22 +0800] [26150] [INFO] Using worker: sync
[2019-06-12 22:45:22 +0800] [26153] [INFO] Booting worker with pid: 26153
[2019-06-12 22:45:22 +0800] [26153] [ERROR] Exception in worker process
Traceback (most recent call last):
  File "/usr/local/python3/lib/python3.6/site-packages/gunicorn/arbiter.py", line 583, in spawn_worker
    worker.init_process()
  File "/usr/local/python3/lib/python3.6/site-packages/gunicorn/workers/base.py", line 129, in init_process
    self.load_wsgi()
  File "/usr/local/python3/lib/python3.6/site-packages/gunicorn/workers/base.py", line 138, in load_wsgi
    self.wsgi = self.app.wsgi()
  File "/usr/local/python3/lib/python3.6/site-packages/gunicorn/app/base.py", line 67, in wsgi
    self.callable = self.load()
  File "/usr/local/python3/lib/python3.6/site-packages/gunicorn/app/wsgiapp.py", line 52, in load
    return self.load_wsgiapp()
  File "/usr/local/python3/lib/python3.6/site-packages/gunicorn/app/wsgiapp.py", line 41, in load_wsgiapp
    return util.import_app(self.app_uri)
  File "/usr/local/python3/lib/python3.6/site-packages/gunicorn/util.py", line 350, in import_app
    __import__(module)
ModuleNotFoundError: No module named 'mac_auth'
[2019-06-12 22:45:22 +0800] [26153] [INFO] Worker exiting (pid: 26153)
[2019-06-12 22:45:22 +0800] [26150] [INFO] Shutting down: Master
[2019-06-12 22:45:22 +0800] [26150] [INFO] Reason: Worker failed to boot.
